Workbook

Sheet Test Summary
A1: FIWDEE – Integration Test Design (backend + PostgreSQL, เวอร์ชัน develop ล่าสุด)
A2: No | B2: Integration area | C2: Test Strategy | D2: No. of Test Cases | E2: Pass | F2: Fail | G2: No run | H2: Block | I2: Remark / Defect ID
A3: A. Repository + PostgreSQL
A4: 1 | B4: IT01 – BookingRepository – query หาการจองที่ชนกัน (JPQL จริงบน PostgreSQL) | C4: Boundary Value (Robustness, ขอบด้านเดียว) | D4: =COUNTA(IT01_ConflictQuery_BVA!$A$11:$A$28) -> 18 | E4: =COUNTIF(IT01_ConflictQuery_BVA!$G$11:$G$28,"Pass") -> 18 | F4: =COUNTIF(IT01_ConflictQuery_BVA!$G$11:$G$28,"Fail") -> 0 | G4: =COUNTIF(IT01_ConflictQuery_BVA!$G$11:$G$28,"No run") -> 0 | H4: =COUNTIF(IT01_ConflictQuery_BVA!$G$11:$G$28,"Block") -> 0
A5: 2 | B5: IT02 – Repository / JPA mapping บน PostgreSQL จริง | C5: Weak Robust Equivalence Class | D5: =COUNTA(IT02_JpaMapping_EC!$A$21:$A$34) -> 14 | E5: =COUNTIF(IT02_JpaMapping_EC!$F$21:$F$34,"Pass") -> 14 | F5: =COUNTIF(IT02_JpaMapping_EC!$F$21:$F$34,"Fail") -> 0 | G5: =COUNTIF(IT02_JpaMapping_EC!$F$21:$F$34,"No run") -> 0 | H5: =COUNTIF(IT02_JpaMapping_EC!$F$21:$F$34,"Block") -> 0
A6: B. API + Security
A7: 3 | B7: IT03 – Authentication: AuthController + JwtAuthenticationFilter + UserRepository | C7: Weak Robust Equivalence Class | D7: =COUNTA(IT03_AuthJwt_EC!$A$23:$A$34) -> 12 | E7: =COUNTIF(IT03_AuthJwt_EC!$F$23:$F$34,"Pass") -> 12 | F7: =COUNTIF(IT03_AuthJwt_EC!$F$23:$F$34,"Fail") -> 0 | G7: =COUNTIF(IT03_AuthJwt_EC!$F$23:$F$34,"No run") -> 0 | H7: =COUNTIF(IT03_AuthJwt_EC!$F$23:$F$34,"Block") -> 0
A8: 4 | B8: IT04 – สิทธิ์การเข้าถึงตาม role: SecurityConfig + JwtAuthenticationFilter + Controller | C8: Decision Table (Extended Entry: role × endpoint) | D8: =COUNTA(IT04_RoleAccess_DT!$B$27:$B$76) -> 50 | E8: =COUNTIF(IT04_RoleAccess_DT!$G$27:$G$76,"Pass") -> 50 | F8: =COUNTIF(IT04_RoleAccess_DT!$G$27:$G$76,"Fail") -> 0 | G8: =COUNTIF(IT04_RoleAccess_DT!$G$27:$G$76,"No run") -> 0 | H8: =COUNTIF(IT04_RoleAccess_DT!$G$27:$G$76,"Block") -> 0
A9: 5 | B9: IT05 – รูปแบบ error ของ API: Bean Validation + GlobalExceptionHandler | C9: Weak Robust Equivalence Class | D9: =COUNTA(IT05_ErrorContract_EC!$A$24:$A$33) -> 10 | E9: =COUNTIF(IT05_ErrorContract_EC!$F$24:$F$33,"Pass") -> 10 | F9: =COUNTIF(IT05_ErrorContract_EC!$F$24:$F$33,"Fail") -> 0 | G9: =COUNTIF(IT05_ErrorContract_EC!$F$24:$F$33,"No run") -> 0 | H9: =COUNTIF(IT05_ErrorContract_EC!$F$24:$F$33,"Block") -> 0
A10: C. Business flow ผ่าน API + DB
A11: 6 | B11: IT06 – สร้างการจอง: BookingController → BookingServiceImpl → Repository ทั้ง 7 ตัว → PostgreSQL | C11: Decision Table (Limited Entry) | D11: =COUNTA(IT06_CreateBookingApi_DT!$B$25:$B$39) -> 15 | E11: =COUNTIF(IT06_CreateBookingApi_DT!$G$25:$G$39,"Pass") -> 15 | F11: =COUNTIF(IT06_CreateBookingApi_DT!$G$25:$G$39,"Fail") -> 0 | G11: =COUNTIF(IT06_CreateBookingApi_DT!$G$25:$G$39,"No run") -> 0 | H11: =COUNTIF(IT06_CreateBookingApi_DT!$G$25:$G$39,"Block") -> 0
A12: 7 | B12: IT07 – ตรวจช่วงเวลาว่าง: BookingController → AvailabilityServiceImpl → BusinessHours/Skill/Room/Booking repositories | C12: Boundary Value (จำนวนทรัพยากรที่เหลือ และเวลาปิดร้าน) | D12: =COUNTA(IT07_AvailabilityApi_BVA!$A$11:$A$20) -> 10 | E12: =COUNTIF(IT07_AvailabilityApi_BVA!$F$11:$F$20,"Pass") -> 10 | F12: =COUNTIF(IT07_AvailabilityApi_BVA!$F$11:$F$20,"Fail") -> 0 | G12: =COUNTIF(IT07_AvailabilityApi_BVA!$F$11:$F$20,"No run") -> 0 | H12: =COUNTIF(IT07_AvailabilityApi_BVA!$F$11:$F$20,"Block") -> 0
A13: 8 | B13: IT08 – ยกเลิกการจอง: BookingController → BookingServiceImpl → State Pattern → PostgreSQL | C13: Decision Table (Limited Entry) | D13: =COUNTA(IT08_CancelApi_DT!$B$23:$B$30) -> 8 | E13: =COUNTIF(IT08_CancelApi_DT!$G$23:$G$30,"Pass") -> 8 | F13: =COUNTIF(IT08_CancelApi_DT!$G$23:$G$30,"Fail") -> 0 | G13: =COUNTIF(IT08_CancelApi_DT!$G$23:$G$30,"No run") -> 0 | H13: =COUNTIF(IT08_CancelApi_DT!$G$23:$G$30,"Block") -> 0
A14: 9 | B14: IT09 – ชำระเงินและคืนเงิน: Payment/RefundController → Service → Strategy (ของจริง) → PostgreSQL | C14: Weak Robust Equivalence Class (+ Stub ที่ Payment Strategy) | D14: =COUNTA(IT09_PaymentRefundApi_EC!$A$21:$A$35) -> 15 | E14: =COUNTIF(IT09_PaymentRefundApi_EC!$F$21:$F$35,"Pass") -> 15 | F14: =COUNTIF(IT09_PaymentRefundApi_EC!$F$21:$F$35,"Fail") -> 0 | G14: =COUNTIF(IT09_PaymentRefundApi_EC!$F$21:$F$35,"No run") -> 0 | H14: =COUNTIF(IT09_PaymentRefundApi_EC!$F$21:$F$35,"Block") -> 0
A15: 10 | B15: IT10 – Check-in และคิว: FrontDesk/QueueController → QueueServiceImpl → Event → QueueListener (Observer) → PostgreSQL | C15: Weak Robust Equivalence Class (+ Spy ที่ QueueListener) | D15: =COUNTA(IT10_CheckInQueue_EC!$A$20:$A$30) -> 11 | E15: =COUNTIF(IT10_CheckInQueue_EC!$F$20:$F$30,"Pass") -> 11 | F15: =COUNTIF(IT10_CheckInQueue_EC!$F$20:$F$30,"Fail") -> 0 | G15: =COUNTIF(IT10_CheckInQueue_EC!$F$20:$F$30,"No run") -> 0 | H15: =COUNTIF(IT10_CheckInQueue_EC!$F$20:$F$30,"Block") -> 0
A16: D. End-to-end scenario
A17: 11 | B17: IT11 – Flow ทั้งระบบตาม sequence diagram (หลาย controller ต่อเนื่องกันบนฐานข้อมูลเดียว) | C17: Scenario-based (Use-case flow) แบ่งกลุ่มแบบ Equivalence Class ของเส้นทาง | D17: =COUNTA(IT11_EndToEndFlow_SC!$A$20:$A$27) -> 8 | E17: =COUNTIF(IT11_EndToEndFlow_SC!$F$20:$F$27,"Pass") -> 8 | F17: =COUNTIF(IT11_EndToEndFlow_SC!$F$20:$F$27,"Fail") -> 0 | G17: =COUNTIF(IT11_EndToEndFlow_SC!$F$20:$F$27,"No run") -> 0 | H17: =COUNTIF(IT11_EndToEndFlow_SC!$F$20:$F$27,"Block") -> 0
A18: 12 | B18: IT12 – ผลของการตั้งค่าหลังบ้านต่อการจอง: AdminResourceController → Room/Service/Therapist/Shop service → Booking/Availability | C18: Weak Robust Equivalence Class (ข้ามโมดูล) | D18: =COUNTA(IT12_AdminConfigImpact_EC!$A$19:$A$26) -> 8 | E18: =COUNTIF(IT12_AdminConfigImpact_EC!$F$19:$F$26,"Pass") -> 8 | F18: =COUNTIF(IT12_AdminConfigImpact_EC!$F$19:$F$26,"Fail") -> 0 | G18: =COUNTIF(IT12_AdminConfigImpact_EC!$F$19:$F$26,"No run") -> 0 | H18: =COUNTIF(IT12_AdminConfigImpact_EC!$F$19:$F$26,"Block") -> 0
A19: Total | D19: =SUMPRODUCT(ISNUMBER(D3:D18)*D3:D18) -> 179 | E19: =SUMPRODUCT(ISNUMBER(E3:E18)*E3:E18) -> 179 | F19: =SUMPRODUCT(ISNUMBER(F3:F18)*F3:F18) -> 0 | G19: =SUMPRODUCT(ISNUMBER(G3:G18)*G3:G18) -> 0 | H19: =SUMPRODUCT(ISNUMBER(H3:H18)*H3:H18) -> 0
A21: วิธีใช้: หลังรัน ./mvnw test -Dgroups=integration ให้กรอก Actual Result และเลือก Status ในแต่ละชีต

Sheet Defect Summary
A1: DEF-013 ขึ้นไป = พบใหม่ในรอบ Integration (static review + ออกแบบเคส) • DEF เดิมที่รอบนี้ยืนยันซ้ำอยู่ท้ายตาราง • ยืนยันอีกครั้งหลังรันจริง
A2: No | B2: Defect No | C2: Defect Title | D2: Report Date | E2: Fix date | F2: Reporter | G2: Defect Status | H2: Defect Severity | I2: Defect Priority | J2: Closed By | K2: Defect Details
A3: 1 | B3: DEF-013 | C3: หมอนวดกด complete แล้ว booking เป็น COMPLETED ทันทีทั้งที่ยังไม่ชำระเงิน | D3: 46305 | E3: 46305 | F3: Piyachayanin | G3: Open | H3: High | I3: High | J3: Piyachayanin | K3: service/impl/TherapistExecutionServiceImpl.completeService ตั้ง status เองโดยไม่ผ่าน InServiceState.complete (ที่บังคับว่าต้องชำระก่อน) • sequence-diagram Scenario 3 Phase B ระบุว่า booking ต้องคงเป็น IN_SERVICE จนกว่าจะชำระ • เกี่ยวกับ Open Question Q5 ของรอบ Unit • IT11-TC002
A4: 2 | B4: DEF-014 | C4: ชำระเงินระหว่าง IN_SERVICE แล้วคิวค้าง IN_SERVICE ห้องค้าง OCCUPIED และหมอนวดกดจบงานไม่ได้ | D4: 46305 | E4: 46306 | F4: Piyachayanin | G4: Open | H4: High | I4: High | J4: Piyachayanin | K4: service/impl/PaymentServiceImpl ตั้ง booking เป็น COMPLETED โดยไม่ publish event (DEF-002) จึงไม่มีใครปิดคิว/เปลี่ยนห้อง • จากนั้น completeService ปฏิเสธเพราะ booking ไม่ใช่ IN_SERVICE • ผิด Scenario 3 Phase D • IT11-TC003
A5: 3 | B5: DEF-015 | C5: endpoint หลายตัวไม่จำกัด role ตาม Use-case Matrix | D5: 46305 | E5: 46307 | F5: Piyachayanin | G5: Open | H5: High | I5: High | J5: Piyachayanin | K5: SecurityConfig ไม่มีกฎสำหรับ PATCH /api/bookings/*/check-in (UC-12 = Receptionist), /api/therapist/** (UC-16/17 = Therapist) และให้ RECEPTIONIST เขียน /api/admin/rooms, services, therapists, shop ได้ (UC-23–27 = Owner) • ลูกค้าจึง check-in และเริ่มงานแทนหมอนวดได้ • TASKS 2.7, 2.8 ยังไม่เสร็จ • IT04 (E9, E10), IT12-TC008
A6: 4 | B6: DEF-016 | C6: ลูกค้าดูข้อมูลการชำระเงินของ booking คนอื่นได้ | D6: 46305 | E6: 46308 | F6: Piyachayanin | G6: Open | H6: Medium | I6: High | J6: Piyachayanin | K6: PaymentController.getPaymentByBooking / getReceipt ไม่รับผู้ใช้ปัจจุบันและ service ไม่ตรวจเจ้าของ • UC-20 ลูกค้าดูได้เฉพาะของตัวเอง (My) • IT09-TC014
A7: 5 | B7: DEF-017 | C7: จองช่วงเวลาเดียวกันพร้อมกันได้หลายรายการ (double booking) | D7: 46305 | E7: 46309 | F7: Piyachayanin | G7: Open | H7: High | I7: Medium | J7: Piyachayanin | K7: service/impl/BookingServiceImpl.createBooking ตรวจการชนด้วย SELECT แล้วค่อย INSERT โดยไม่มี lock หรือ constraint • request ที่มาพร้อมกันผ่านการตรวจทั้งหมด • UC-08c • ผลอาจต่างกันในแต่ละรอบที่รัน (race condition) • IT11-TC007
A8: 6 | B8: DEF-018 | C8: การชำระเงินที่ล้มเหลวไม่เหลือหลักฐานในฐานข้อมูล | D8: 46305 | E8: 46310 | F8: Piyachayanin | G8: Open | H8: Medium | I8: Medium | J8: Piyachayanin | K8: service/impl/PaymentServiceImpl save payment FAILED แล้ว throw ValidationException ใน @Transactional เดียวกัน จึงถูก rollback • Unit test (verify save FAILED) ผ่านเพราะใช้ mock แต่ของจริงไม่บันทึก • UC-19b • IT09-TC012
A9: 7 | B9: DEF-019 | C9: query parameter ผิดชนิด (enum / วันที่) ได้ 500 แทน 400 | D9: 46305 | E9: 46311 | F9: Piyachayanin | G9: Open | H9: Low | I9: Medium | J9: Piyachayanin | K9: GlobalExceptionHandler ไม่มี handler ของ MethodArgumentTypeMismatchException จึงตกไปที่ handler ของ Exception • frontend แสดง "internal server error" แทนข้อความที่บอกว่า input ผิด • IT05-TC007, TC008

Sheet Test Environment
A1: สภาพแวดล้อมและข้อมูลตั้งต้นของ Integration Test
A2: รายการ | B2: ค่า | C2: หมายเหตุ
A3: ฐานข้อมูล | B3: PostgreSQL 16 (container fiwdee-postgres) ฐาน fiwdee_test | C3: สร้างครั้งเดียว: docker exec fiwdee-postgres createdb -U postgres fiwdee_test
A4: Spring profile | B4: it (src/test/resources/application-it.properties) | C4: ddl-auto = create-drop • ปิด DemoDataSeeder และ AdminAccountInitializer ให้เหลือแต่ DataSeeder
A5: คำสั่งรัน | B5: ./mvnw test -Dgroups=integration | C5: Windows: mvnw.cmd test "-Dgroups=integration" • ข้ามเคส defect: เติม -DexcludedGroups=known-defect
A6: วัน D | B6: วันนี้ + 7 วัน | C6: ใช้กับการจองผ่าน API • ทุกเคสสร้างกะ 10:00–18:00 ของหมอนวดทุกคนในวัน D ไว้ก่อน (ให้ผลเหมือนเดิมแม้ทีมแก้ DEF-005)
A7: Owner | B7: owner / pass123 | C7: จาก DataSeeder
A8: Receptionist | B8: receptionist / pass123 | C8: จาก DataSeeder
A9: Therapist | B9: therapist1 – therapist6 / pass123 | C9: ทักษะ: THAI = 1, 2, 4, 6 • AROMA = 2, 3, 5, 6 • HOT_OIL = 3, 4, 6 • FOOT = 1, 5, 6
A10: Customer | B10: สมัครใหม่ทุกเคสผ่าน POST /api/auth/register | C10: อีเมลขึ้นต้น it. แล้วถูกลบตอนล้างข้อมูล
A11: ห้อง | B11: Room 1, Room 2 = SINGLE • Room 3, 4 = COUPLE • Room 5 = VIP • Room 6 = FOOT_MASSAGE | C11: buffer ทำความสะอาด 15 นาทีทุกห้อง
A12: บริการ | B12: THAI 60/90/120 = 500/700/900 (SINGLE) • AROMA 700/950/1200 (SINGLE) • HOT_OIL (VIP) • FOOT (FOOT_MASSAGE)
A13: เวลาทำการ | B13: 10:00–22:00 ทุกวัน
A14: ช่วงใกล้เที่ยงคืน | B14: เคสที่ใช้ booking วันนี้ (IT10, IT11-TC001–003) ข้ามตัวเองช่วง 23:50–00:00 | C14: แสดงเป็น Skipped เพราะโค้ดใช้ LocalDateTime.now() ตรง ๆ (Open Question Q1 ของรอบ Unit)
A15: การล้างข้อมูล | B15: หลังทุกเคส: TRUNCATE bookings, payments, refunds, reviews, queue_items และลบข้อมูลที่ขึ้นต้น it. / IT- | C15: คืนค่าห้อง บริการ ผู้ใช้ และเวลาทำการเป็นค่าตั้งต้น

Sheet IT01_ConflictQuery_BVA
A1: Test Case Design and Test Results | K1: ปลายช่วงที่ค้นหา เทียบ 11:00 | L1: ต้นช่วงที่ค้นหา เทียบ 12:00 | M1: ห้อง: ต้นช่วง เทียบ 12:15 | N1: ห้อง: ปลายช่วง เทียบ 10:45
J2: ขอบ-1 | K2: 10:59 | L2: 11:59 | M2: 12:14 | N2: 10:44
A3: Project Name: | B3: BookingRepository – query หาการจองที่ชนกัน (JPQL จริงบน PostgreSQL) | F3: Student ID: | G3: 673380049-4 | J3: ขอบ | K3: 11:00 | L3: 12:00 | M3: 12:15 | N3: 10:45
A4: Test Strategy: | B4: Integration testing - Boundary Value (Robustness, ขอบด้านเดียว) | F4: Designer: | G4: Piyachayanin | J4: ขอบ+1 | K4: 11:01 | L4: 12:01 | M4: 12:16 | N4: 10:46
A5: Test Environtment: | B5: Lenovo LOQ 15AHP11, CPU AMD Ryzen 7 250, Memory 16 GB DDR5, GPU NVIDIA GeForce RTX 5050 Laptop, OS Window 11 | F5: Date: | G5: 46305
A6: Method under test: | B6: findConflictingTherapistBookings • findConflictingRoomBookingsWithCleaningBuffer (buffer 15 นาที) • excludedStatuses = [CANCELLED, NO_SHOW]
A7: Requirement อ้างอิง: | B7: UC-08a, UC-08b, UC-08c • BR-RES-01 (buffer 15 นาที)
A9: Test Case ID | B9: Input | E9: Expected Result | F9: Actual Result | G9: Status (Pass/Fail/No run)
B10: query | C10: ช่วงที่ค้นหา (วัน D) | D10: booking เดิม
A11: IT01-TC001 | B11: therapist | C11: 09:59–10:59 | D11: CONFIRMED | E11: 0 รายการ (ขอบ−1) | F11: 0 รายการ | G11: Pass
A12: IT01-TC002 | B12: therapist | C12: 10:00–11:00 | D12: CONFIRMED | E12: 0 รายการ (จบตรงกับเวลาเริ่ม = ไม่ชน) | F12: 0 รายการ | G12: Pass
A13: IT01-TC003 | B13: therapist | C13: 10:01–11:01 | D13: CONFIRMED | E13: 1 รายการ (ขอบ+1) | F13: 1 รายการ | G13: Pass
A14: IT01-TC004 | B14: therapist | C14: 11:59–12:59 | D14: CONFIRMED | E14: 1 รายการ | F14: 1 รายการ | G14: Pass
A15: IT01-TC005 | B15: therapist | C15: 12:00–13:00 | D15: CONFIRMED | E15: 0 รายการ (เริ่มตรงกับเวลาจบ = ไม่ชน) | F15: 0 รายการ | G15: Pass
A16: IT01-TC006 | B16: therapist | C16: 12:01–13:01 | D16: CONFIRMED | E16: 0 รายการ | F16: 0 รายการ | G16: Pass
A17: IT01-TC007 | B17: therapist | C17: 11:00–12:00 (ตรงกันพอดี) | D17: CONFIRMED | E17: 1 รายการ (nom) | F17: 1 รายการ | G17: Pass
A18: IT01-TC008 | B18: therapist | C18: 10:00–13:00 (ครอบทั้งช่วง) | D18: CONFIRMED | E18: 1 รายการ | F18: 1 รายการ | G18: Pass
A19: IT01-TC009 | B19: room + buffer | C19: 12:14–13:14 | D19: CONFIRMED | E19: 1 รายการ (ยังอยู่ใน buffer) | F19: 1 รายการ | G19: Pass
A20: IT01-TC010 | B20: room + buffer | C20: 12:15–13:15 | D20: CONFIRMED | E20: 0 รายการ (พ้น buffer พอดี) | F20: รายการ | G20: Pass
A21: IT01-TC011 | B21: room + buffer | C21: 12:16–13:16 | D21: CONFIRMED | E21: 0 รายการ | F21: 0 รายการ | G21: Pass
A22: IT01-TC012 | B22: room + buffer | C22: 09:44–10:44 | D22: CONFIRMED | E22: 0 รายการ | F22: 0 รายการ | G22: Pass
... A28: IT01-TC018 | B28: therapist (therapist2) | C28: 11:00–12:00 | D28: CONFIRMED ของ therapist1 | E28: 0 รายการ (คนละหมอนวด) | F28: 0 รายการ | G28: Pass

Sheet IT02_JpaMapping_EC
A1: Equivalence Class Design
A2: Valid EC | E2: Invalid EC
A3: EC ID | B3: Condition | E3: EC ID | F3: Condition
A4: V1 | B4: @EntityGraph โหลดความสัมพันธ์ครบ ใช้นอก transaction ได้ | E4: I1 | F4: payment ซ้ำ booking เดียวกัน
A5: V2 | B5: query ที่ parameter เป็น null ทั้งหมด | E5: I2 | F5: review ซ้ำ booking เดียวกัน
A6: V3 | B6: ค้นหาแบบไม่สนตัวพิมพ์ | E6: I3 | F6: เลขคิวซ้ำในวันเดียวกัน
A7: V4 | B7: กรองสถานะ / วันที่ / แบ่งหน้า
A8: V5 | B8: รวมยอด payment ตามสถานะและช่วงเวลา (ขอบรวม)
A9: V6 | B9: enum เก็บเป็นข้อความ
A11: Test Case Design and Test Results
A13: Project Name: | B13: Repository / JPA mapping บน PostgreSQL จริง | H13: Student ID: | I13: 673380049-4
A14: Test Strategy: | B14: Integration testing - Weak Robust Equivalence Class | H14: Designer: | I14: Piyachayanin
A15: Test Environtment: | B15: Lenovo LOQ 15AHP11, CPU AMD Ryzen 7 250, Memory 16 GB DDR5, GPU NVIDIA GeForce RTX 5050 Laptop, OS Window 11 | H15: Date: | I15: 46305
A16: Method under test: | B16: findDetailedById (@EntityGraph) • findAdminBookings • findCompletedPaymentsBetween • findUsersPage • unique constraint ของตาราง
A17: Requirement อ้างอิง: | B17: ER diagram (doc/er-diagram.md) • UC-09 (ค้นหา/แบ่งหน้า) • UC-22
A19: Test Case ID | B19: Input | D19: Expected Result | E19: Actual Result | F19: Status (Pass/Fail/No run)
B20: repository / ข้อมูลตั้งต้น | C20: การเรียก
A21: IT02-TC001 | B21: booking D 10:00 | C21: findDetailedById แล้วอ่าน customer, therapist, room, service, durationOption นอก transaction | D21: (V1) อ่านได้ครบ ไม่เกิด LazyInitializationException | E21: อ่านได้ครบ ไม่เกิด LazyInitializationException | F21: Pass
A22: IT02-TC002 | B22: booking 3 รายการ | C22: findAdminBookings(null, null, null, null, page 0 size 10 เรียง startDateTime desc) | D22: (V2) ไม่ error บน PostgreSQL • ได้ 3 รายการ เรียงจากใหม่ไปเก่า | E22: ไม่ error บน PostgreSQL • ได้ 3 รายการ เรียงจากใหม่ไปเก่า | F22: Pass
A23: IT02-TC003 | B23: ลูกค้าชื่อ "Somchai ITSEARCH" | C23: search = "itsearch" | D23: (V3) ได้เฉพาะ booking ของลูกค้าคนนี้ | E23: ได้เฉพาะ booking ของลูกค้าคนนี้ | F23: Pass
A24: IT02-TC004 | B24: booking 3 รายการ | C24: status = CANCELLED | D24: (V4) ได้ 1 รายการ สถานะ CANCELLED | E24: 1 รายการ สถานะ CANCELLED | F24: Pass
A25: IT02-TC005 | B25: booking 3 รายการ | C25: date = D | D25: (V4) ได้ 2 รายการ (ไม่รวม D+1) | E25: 2 รายการ | F25: Pass
A26: IT02-TC006 | B26: booking 3 รายการ | C26: page 0 size 2 | D26: (V4) content 2 รายการ, totalElements 3, totalPages 2 | E26: content 2 รายการ, totalElements 3, totalPages 2 | F26: Pass
A27: IT02-TC007 | B27: payment COMPLETED, REFUNDED, PENDING, FAILED (paidAt อยู่ในช่วง) | C27: findCompletedPaymentsBetween | D27: (V5) ได้ 2 รายการ: COMPLETED กับ REFUNDED | E27: ได้ 2 รายการ: COMPLETED กับ REFUNDED | F27: Pass
A28: IT02-TC008 | B28: paidAt = ต้นช่วง, ปลายช่วง, ต้นช่วง−1 วินาที, ปลายช่วง+1 วินาที | C28: findCompletedPaymentsBetween | D28: (V5) ได้ 2 รายการที่อยู่ตรงขอบพอดี | E28: ได้ 2 รายการที่อยู่ตรงขอบพอดี | F28: Pass
A29: IT02-TC009 | B29: ผู้ใช้จาก seed | C29: findUsersPage(null, null) | D29: (V2) ไม่ error • ได้ผู้ใช้อย่างน้อย 8 คน | E29: ไม่ error | F29: Pass
A30: IT02-TC010 | B30: ผู้ใช้จาก seed | C30: findUsersPage(THERAPIST, "five") | D30: (V3) ได้ 1 คน (Therapist Five) | E30: ด้ 1 คน | F30: Pass
A31: IT02-TC011 | B31: booking ที่มี payment แล้ว | C31: save payment ใบที่ 2 | D31: (I1) DataIntegrityViolationException | E31: DataIntegrityViolationException | F31: Pass
A32: IT02-TC012 | B32: booking ที่มี review แล้ว | C32: save review ใบที่ 2 | D32: (I2) DataIntegrityViolationException | E32: DataIntegrityViolationException | F32: Pass
... A34: IT02-TC014 | B34: booking CONFIRMED | C34: SELECT status FROM bookings (SQL ตรง) | D34: (V6) ได้ข้อความ "CONFIRMED" | E34: ได้ข้อความ "CONFIRMED" | F34: Pass

Sheet IT03_AuthJwt_EC
A1: Equivalence Class Design
A2: Valid EC | E2: Invalid EC
A3: EC ID | B3: Condition | E3: EC ID | F3: Condition
A4: V1 | B4: สมัครแล้วใช้ token ได้ทันที | E4: I1 | F4: รหัสผ่านผิด
A5: V2 | B5: login บัญชี seed แล้วใช้สิทธิ์ตาม role | E5: I2 | F5: ไม่มี token
A6: V3 | B6: แก้โปรไฟล์ตัวเองแล้วบันทึกลงฐานข้อมูล | E6: I3 | F6: token ผิดรูป
A7: V4 | B7: login แล้วบันทึก last_login_at | E7: I4 | F7: token หมดอายุ
E8: I5 | F8: token เซ็นด้วย key อื่น
E9: I6 | F9: ผู้ใช้ถูกระงับหลังได้ token
E10: I7 | F10: อีเมลซ้ำ
E11: I8 | F11: ข้อมูลสมัครไม่ผ่าน @Valid
A13: Test Case Design and Test Results
A15: Project Name: | B15: Authentication: AuthController + JwtAuthenticationFilter + UserRepository | H15: Student ID: | I15: 673380049-4
A16: Test Strategy: | B16: Integration testing - Weak Robust Equivalence Class | H16: Designer: | I16: Piyachayanin
A17: Test Environtment: | B17: Lenovo LOQ 15AHP11, CPU AMD Ryzen 7 250, Memory 16 GB DDR5, GPU NVIDIA GeForce RTX 5050 Laptop, OS Window 11 | H17: Date: | I17: 46305
A18: Method under test: | B18: POST /api/auth/register • POST /api/auth/login • GET/PUT /api/auth/me • ทุก request ผ่าน JwtAuthenticationFilter
A19: Requirement อ้างอิง: | B19: UC-01, UC-02, UC-03 • SRS 7.4 • AGENTS.md §5 (ApiResponse)
A21: Test Case ID | B21: Input | D21: Expected Result | E21: Actual Result | F21: Status (Pass/Fail/No run)
B22: ข้อมูลตั้งต้น | C22: Request
A23: IT03-TC001 | B23: − | C23: POST /register (อีเมลใหม่) → GET /me ด้วย token ที่ได้ | D23: (V1) 201 มี token • /me 200 role CUSTOMER อีเมลตรงกัน | E23: 201 | F23: Pass
A24: IT03-TC002 | B24: owner / pass123 | C24: POST /login → GET /api/admin/users ด้วย token | D24: (V2) 200 role OWNER • /api/admin/users 200 | E24: 200 | F24: Pass
A25: IT03-TC003 | B25: owner | C25: POST /login รหัส "wrong" | D25: (I1) 401 {success:false, message:"อีเมลหรือรหัสผ่านไม่ถูกต้อง"} | E25: 401 | F25: Pass
A26: IT03-TC004 | B26: − | C26: GET /me ไม่มี header Authorization | D26: (I2) 401 JSON message "Authentication required..." | E26: 401 | F26: Pass
A27: IT03-TC005 | B27: − | C27: GET /me ด้วย "Bearer abc" | D27: (I3) 401 | E27: 401 | F27: Pass
A28: IT03-TC006 | B28: token หมดอายุ (secret เดียวกัน, อายุ −1 วินาที) | C28: GET /me | D28: (I4) 401 | E28: 401 | F28: Pass
A29: IT03-TC007 | B29: token จาก secret อื่น | C29: GET /me | D29: (I5) 401 | E29: 401 | F29: Pass
A30: IT03-TC008 | B30: ลูกค้าได้ token แล้วถูกตั้ง is_active = false | C30: GET /me | D30: (I6) 401 (filter ตรวจสถานะจากฐานข้อมูลทุก request) | E30: 401 | F30: Pass
A31: IT03-TC009 | B31: ลูกค้า login อยู่ | C31: PUT /me แก้ชื่อ และ healthNotes → GET /me | D31: (V3) 200 • ค่าใหม่อยู่ในตาราง users / customers และ /me แสดงค่าใหม่ | E31: 200 | F31: Pass
A32: IT03-TC010 | B32: อีเมลนี้สมัครไว้แล้ว | C32: POST /register อีเมลเดิม | D32: (I7) 409 JSON success:false | E32: 409 | F32: Pass
A33: IT03-TC011 | B33: − | C33: POST /register email "abc", password "123" | D33: (I8) 400 message "Validation failed" • errors มี email และ password | E33: 400 | F33: Pass
A34: IT03-TC012 | B34: owner | C34: POST /login สำเร็จ | D34: (V4) users.last_login_at ไม่เป็น null | E34: users.last_login_at ไม่เป็น null | F34: Pass

Sheet IT04_RoleAccess_DT
A1: Condition | B1: Rule#1 | C1: Rule#2 | D1: Rule#3 | E1: Rule#4 | F1: Rule#5
A2: C1: role ของผู้เรียก | B2: ANON | C2: CUSTOMER | D2: THERAPIST | E2: RECEPTIONIST | F2: OWNER
A3: Action
A4: E1: GET /services | B4: ผ่าน | C4: ผ่าน | D4: ผ่าน | E4: ผ่าน | F4: ผ่าน
A5: E2: GET /bookings/my | B5: 401 | C5: ผ่าน | D5: ผ่าน | E5: ผ่าน | F5: ผ่าน
A6: E3: GET /admin/rooms | B6: 401 | C6: 403 | D6: 403 | E6: ผ่าน | F6: ผ่าน
A7: E4: GET /admin/users | B7: 401 | C7: 403 | D7: 403 | E7: 403 | F7: ผ่าน
A8: E5: GET /admin/reports/revenue | B8: 401 | C8: 403 | D8: 403 | E8: 403 | F8: ผ่าน
A9: E6: PATCH /bookings/{x}/status | B9: 401 | C9: 403 | D9: 403 | E9: ผ่าน | F9: ผ่าน
A10: E7: POST /payments/{x}/refund | B10: 401 | C10: 403 | D10: 403 | E10: ผ่าน | F10: ผ่าน
A11: E8: GET /admin/queue | B11: 401 | C11: 403 | D11: 403 | E11: ผ่าน | F11: ผ่าน
A12: E9: PATCH /bookings/{x}/check-in | B12: 401 | C12: 403 ⚠ | D12: 403 ⚠ | E12: ผ่าน | F12: ผ่าน
A13: E10: POST /therapist/queue/{x}/start | B13: 401 | C13: 403 ⚠ | D13: ผ่าน | E13: ผ่าน | F13: ผ่าน
A14: Impossible
A17: Test Case Design and Test Results
A19: Project Name: | B19: สิทธิ์การเข้าถึงตาม role: SecurityConfig + JwtAuthenticationFilter + Controller | F19: Student ID: | G19: 673380049-4
A20: Test Strategy: | B20: Integration testing - Decision Table (Extended Entry: role × endpoint) | F20: Designer: | G20: Piyachayanin
A21: Test Environtment: | B21: Lenovo LOQ 15AHP11, CPU AMD Ryzen 7 250, Memory 16 GB DDR5, GPU NVIDIA GeForce RTX 5050 Laptop, OS Window 11 | F21: Date: | G21: 46305
A22: Method under test: | B22: SecurityFilterChain.authorizeHttpRequests ทุก endpoint กลุ่มหลัก • ใช้ id 999999 ที่ไม่มีจริง เพื่อแยกผลของ security (401/403) ออกจากผลของ service (404)
A23: Requirement อ้างอิง: | B23: use-case.md §3 (Actor–Use Case Matrix) • TASKS 2.7, 2.8 • SecurityConfig
A25: Rule# | B25: Test Case ID | C25: Input | E25: Expected Result | F25: Actual Result | G25: Status (Pass/Fail/No run)
C26: Endpoint | D26: Role
A27: R1 | B27: IT04-TC001 | C27: E1 GET /api/services | D27: ANON | E27: ผ่านชั้น security (ไม่ใช่ 401/403) • id ที่ไม่มีจริงได้ 404, รายการได้ 200 | F27: ผ่านชั้น security id ที่ไม่มีจริงได้ 404, รายการได้ 200 | G27: Pass
A28: R2 | B28: IT04-TC002 | C28: E1 GET /api/services | D28: CUSTOMER | E28: ผ่านชั้น security (ไม่ใช่ 401/403) • id ที่ไม่มีจริงได้ 404, รายการได้ 200 | F28: ผ่านชั้น security id ที่ไม่มีจริงได้ 404, รายการได้ 200 | G28: Pass
A29: R3 | B29: IT04-TC003 | C29: E1 GET /api/services | D29: THERAPIST | E29: ผ่านชั้น security (ไม่ใช่ 401/403) • id ที่ไม่มีจริงได้ 404, รายการได้ 200 | F29: ผ่านชั้น security id ที่ไม่มีจริงได้ 404, รายการได้ 200 | G29: Pass
A30: R4 | B30: IT04-TC004 | C30: E1 GET /api/services | D30: RECEPTIONIST | E30: ผ่านชั้น security (ไม่ใช่ 401/403) • id ที่ไม่มีจริงได้ 404, รายการได้ 200 | F30: ผ่านชั้น security id ที่ไม่มีจริงได้ 404, รายการได้ 200 | G30: Pass
A31: R5 | B31: IT04-TC005 | C31: E1 GET /api/services | D31: OWNER | E31: ผ่านชั้น security (ไม่ใช่ 401/403) • id ที่ไม่มีจริงได้ 404, รายการได้ 200 | F31: ผ่านชั้น security id ที่ไม่มีจริงได้ 404, รายการได้ 200 | G31: Pass
A32: R1 | B32: IT04-TC006 | C32: E2 GET /api/bookings/my | D32: ANON | E32: 401 JSON "Authentication required..." | F32: 401 | G32: Pass
A33: R2 | B33: IT04-TC007 | C33: E2 GET /api/bookings/my | D33: CUSTOMER | E33: ผ่านชั้น security (ไม่ใช่ 401/403) • id ที่ไม่มีจริงได้ 404, รายการได้ 200 | F33: ผ่านชั้น security id ที่ไม่มีจริงได้ 404, รายการได้ 200 | G33: Pass
A34: R3 | B34: IT04-TC008 | C34: E2 GET /api/bookings/my | D34: THERAPIST | E34: ผ่านชั้น security (ไม่ใช่ 401/403) • id ที่ไม่มีจริงได้ 404, รายการได้ 200 | F34: ผ่านชั้น security id ที่ไม่มีจริงได้ 404, รายการได้ 200 | G34: Pass
A35: R4 | B35: IT04-TC009 | C35: E2 GET /api/bookings/my | D35: RECEPTIONIST | E35: ผ่านชั้น security (ไม่ใช่ 401/403) • id ที่ไม่มีจริงได้ 404, รายการได้ 200 | F35: ผ่านชั้น security id ที่ไม่มีจริงได้ 404, รายการได้ 200 | G35: Pass
A36: R5 | B36: IT04-TC010 | C36: E2 GET /api/bookings/my | D36: OWNER | E36: ผ่านชั้น security (ไม่ใช่ 401/403) • id ที่ไม่มีจริงได้ 404, รายการได้ 200 | F36: ผ่านชั้น security id ที่ไม่มีจริงได้ 404, รายการได้ 200 | G36: Pass
A37: R1 | B37: IT04-TC011 | C37: E3 GET /api/admin/rooms | D37: ANON | E37: 401 JSON "Authentication required..." | F37: 401 | G37: Pass
A38: R2 | B38: IT04-TC012 | C38: E3 GET /api/admin/rooms | D38: CUSTOMER | E38: 403 JSON "Access denied..." | F38: 403 | G38: Pass
A39: R3 | B39: IT04-TC013 | C39: E3 GET /api/admin/rooms | D39: THERAPIST | E39: 403 JSON "Access denied..." | F39: 403 | G39: Pass
A40: R4 | B40: IT04-TC014 | C40: E3 GET /api/admin/rooms | D40: RECEPTIONIST | E40: ผ่านชั้น security (ไม่ใช่ 401/403) • id ที่ไม่มีจริงได้ 404, รายการได้ 200 | F40: ผ่านชั้น security id ที่ไม่มีจริงได้ 404, รายการได้ 200 | G40: Pass
A41: R5 | B41: IT04-TC015 | C41: E3 GET /api/admin/rooms | D41: OWNER | E41: ผ่านชั้น security (ไม่ใช่ 401/403) • id ที่ไม่มีจริงได้ 404, รายการได้ 200 | F41: ผ่านชั้น security id ที่ไม่มีจริงได้ 404, รายการได้ 200 | G41: Pass
A42: R1 | B42: IT04-TC016 | C42: E4 GET /api/admin/users | D42: ANON | E42: 401 JSON "Authentication required..." | F42: 401 | G42: Pass
A43: R2 | B43: IT04-TC017 | C43: E4 GET /api/admin/users | D43: CUSTOMER | E43: 403 JSON "Access denied..." | F43: 403 | G43: Pass
A44: R3 | B44: IT04-TC018 | C44: E4 GET /api/admin/users | D44: THERAPIST | E44: 403 JSON "Access denied..." | F44: 403 | G44: Pass
...

Sheet IT05_ErrorContract_EC
A1: Equivalence Class Design
A2: Valid EC | E2: Invalid EC
A3: EC ID | B3: Condition | E3: EC ID | F3: Condition
A4: V1 | B4: endpoint มีจริง + token ถูกต้อง | E4: I1 | F4: body ขาด field บังคับ
E5: I2 | F5: JSON ผิดรูป
E6: I3 | F6: enum ใน body ผิด
E7: I4 | F7: query parameter บังคับขาด
E8: I5 | F8: ไม่พบข้อมูล
E9: I6 | F9: ค่าเกินช่วง (@Min/@Max)
E10: I7 | F10: query parameter ผิดชนิด (enum / วันที่)
E11: I8 | F11: endpoint ไม่มีจริง
E12: I9 | F12: ทำซ้ำ (conflict)
A14: Test Case Design and Test Results
A16: Project Name: | B16: รูปแบบ error ของ API: Bean Validation + GlobalExceptionHandler | H16: Student ID: | I16: 673380049-4
A17: Test Strategy: | B17: Integration testing - Weak Robust Equivalence Class | H17: Designer: | I17: Piyachayanin
A18: Test Environtment: | B18: Lenovo LOQ 15AHP11, CPU AMD Ryzen 7 250, Memory 16 GB DDR5, GPU NVIDIA GeForce RTX 5050 Laptop, OS Window 11 | H18: Date: | I18: 46305
A19: Method under test: | B19: ทุก controller → GlobalExceptionHandler → ApiResponse {success:false, message, errors?}
A20: Requirement อ้างอิง: | B20: AGENTS.md §5 (ApiResponse contract) • SRS 7 (error handling)
A22: Test Case ID | B22: Input | D22: Expected Result | E22: Actual Result | F22: Status (Pass/Fail/No run)
B23: ผู้เรียก | C23: Request
A24: IT05-TC001 | B24: customer | C24: POST /api/bookings body {} | D24: (I1) 400 message "Validation failed" • errors มี serviceId, durationOptionId, startDateTime | E24: 400 message "Validation failed" | F24: Pass
A25: IT05-TC002 | B25: customer | C25: POST /api/bookings body "{bad json" | D25: (I2) 400 message "Invalid request body..." | E25: 400 message "Invalid request body..." | F25: Pass
A26: IT05-TC003 | B26: receptionist | C26: POST /api/bookings/{id}/payment paymentMethod "BITCOIN" | D26: (I3) 400 | E26: 400 | F26: Pass
A27: IT05-TC004 | B27: ไม่ login | C27: GET /api/bookings/availability (ไม่ส่ง serviceId) | D27: (I4) 400 "Required query parameter 'serviceId' is missing" | E27: 400 | F27: Pass
A28: IT05-TC005 | B28: customer | C28: GET /api/bookings/999999 | D28: (I5) 404 success:false | E28: 404 | F28: Pass
A29: IT05-TC006 | B29: customer | C29: POST /api/bookings/{id}/review overallRating = 6 | D29: (I6) 400 errors.overallRating = "Overall rating must be between 1 and 5" | E29: 400 | F29: Pass
A30: IT05-TC007 | B30: receptionist | C30: PATCH /api/bookings/{id}/status?status=FOO | D30: (I7) 400 | E30: 400 | F30: Pass
A31: IT05-TC008 | B31: receptionist | C31: GET /api/admin/bookings?date=2026-13-45 | D31: (I7) 400 | E31: 400 | F31: Pass
A32: IT05-TC009 | B32: customer | C32: GET /api/nope | D32: (I8) 404 success:false | E32: 404 | F32: Pass
A33: IT05-TC010 | B33: receptionist | C33: POST /api/bookings/{id}/payment ครั้งที่ 2 | D33: (I9) 409 message มี "already been completed" | E33: 409 | F33: Pass

Sheet IT06_CreateBookingApi_DT
A1: Condition | B1: Rule#1 | C1: Rule#2 | D1: Rule#3 | E1: Rule#4 | F1: Rule#5 | G1: Rule#6
A2: C1: หมอนวดที่เลือกไม่ติดคิว (รวมวันหยุด) | B2: Y | C2: Y | D2: N | E2: Y | F2: Y | G2: Y
A3: C2: ห้องที่เลือกว่าง (รวม buffer 15 นาที) | B3: Y | C3: Y | D3: − | E3: N | F3: Y | G3: −
A4: C3: ประเภทห้องตรงกับบริการ | B4: Y | C4: Y | D4: − | E4: − | F4: N | G4: −
A5: C4: ผู้จองเป็นพนักงาน | B5: N | C5: Y | D5: − | E5: − | F5: − | G5: −
A6: C5: มีห้องว่างให้จัดอัตโนมัติ | B6: − | C6: − | D6: − | E6: − | F6: − | G6: N
A7: Action
A8: A1: 201 PENDING / ONLINE | B8: X
A9: A2: 201 CONFIRMED / WALK_IN | C9: X
A10: A3: 409 Conflict | D10: X | E10: X | G10: X
A11: A4: 400 Validation | F11: X
A12: Impossible
A13: C5 ใช้เมื่อไม่ระบุห้อง • เคสสิทธิ์การดู booking (TC013–TC015) เป็นส่วนเสริมของ UC-09
A15: Test Case Design and Test Results
A17: Project Name: | B17: สร้างการจอง: BookingController → BookingServiceImpl → Repository ทั้ง 7 ตัว → PostgreSQL | F17: Student ID: | G17: 673380049-4
A18: Test Strategy: | B18: Integration testing - Decision Table (Limited Entry) | F18: Designer: | G18: Piyachayanin
A19: Test Environtment: | B19: Lenovo LOQ 15AHP11, CPU AMD Ryzen 7 250, Memory 16 GB DDR5, GPU NVIDIA GeForce RTX 5050 Laptop, OS Window 11 | F19: Date: | G19: 46305
A20: Method under test: | B20: POST /api/bookings • GET /api/bookings/my • GET /api/bookings/{id}
A21: Requirement อ้างอิง: | B21: UC-07, UC-08a–c, UC-09 • BR-RES-01 • sequence-diagram Scenario 1
A23: Rule# | B23: Test Case ID | C23: Input | E23: Expected Result | F23: Actual Result | G23: Status (Pass/Fail/No run)
C24: สภาพข้อมูลวัน D | D24: Request
A25: R1 | B25: IT06-TC001 | C25: ว่างทั้งหมด | D25: customer: THAI 60, therapist1, Room 1, D 11:00 | E25: 201 status PENDING, channel ONLINE, totalPrice 500.00, end 12:00 • มีแถวในตาราง bookings ของลูกค้าคนนี้ | F25: 201 | G25: Pass
A26: R2 | B26: IT06-TC002 | C26: ว่างทั้งหมด | D26: receptionist: customerId ของลูกค้า, D 11:00 | E26: 201 status CONFIRMED, channel WALK_IN | F26: 201 | G26: Pass
A27: R1 | B27: IT06-TC003 | C27: ว่างทั้งหมด | D27: customer: ไม่ระบุหมอนวดและห้อง | E27: 201 ได้หมอนวดที่มีทักษะ THAI และห้องประเภท SINGLE | F27: 201 | G27: Pass
A28: R3 | B28: IT06-TC004 | C28: therapist1 ติด 11:00–12:00 | D28: customer คนที่ 2: therapist1, Room 2, D 11:30 | E28: 409 "...already booked for this time slot" | F28: 409 | G28: Pass
A29: R1 | B29: IT06-TC005 | C29: therapist1 ติด 11:00–12:00 (Room 1) | D29: therapist1, Room 2, D 12:00 | E29: 201 (เริ่มตรงกับเวลาจบได้) | F29: 201 | G29: Pass
A30: R4 | B30: IT06-TC006 | C30: Room 1 ติด 11:00–12:00 | D30: therapist2, Room 1, D 12:10 | E30: 409 "...cleaning buffer..." | F30: 409 | G30: Pass
A31: R1 | B31: IT06-TC007 | C31: Room 1 ติด 11:00–12:00 | D31: therapist2, Room 1, D 12:15 | E31: 201 | F31: 201 | G31: Pass
A32: R1 | B32: IT06-TC008 | C32: booking 11:00–12:00 ถูก CANCELLED | D32: therapist1, Room 1, D 11:00 | E32: 201 (สถานะยกเลิกไม่ล็อกเวลา) | F32: 201 | G32: Pass
A33: R3 | B33: IT06-TC009 | C33: therapist1 มีตารางวัน D เป็นวันหยุด | D33: therapist1, Room 1, D 11:00 | E33: 409 "...is off on this date" | F33: 409 | G33: Pass
A34: R5 | B34: IT06-TC010 | C34: ว่างทั้งหมด | D34: THAI กับ Room 5 (VIP) | E34: 400 "Selected room type VIP is not suitable..." | F34: 400 | G34: Pass
A35: R5 | B35: IT06-TC011 | C35: ว่างทั้งหมด | D35: serviceId = THAI, durationOptionId ของ AROMA | E35: 400 "Duration option does not belong..." | F35: 400 | G35: Pass
A36: R6 | B36: IT06-TC012 | C36: Room 1 และ Room 2 ติด 11:00–12:00 | D36: ไม่ระบุห้อง, therapist4, D 11:00 | E36: 409 "No suitable rooms available..." | F36: 409 | G36: Pass
A37: R1 | B37: IT06-TC013 | C37: ลูกค้าจองแล้ว 1 รายการ | D37: GET /api/bookings/my | E37: 200 มีรายการนี้ status PENDING | F37: 200 | G37: Pass
A38: R1 | B38: IT06-TC014 | C38: booking ของลูกค้า A | D38: ลูกค้า B: GET /api/bookings/{id} | E38: 403 "...only view your own bookings" | F38: 403 | G38: Pass
A39: R1 | B39: IT06-TC015 | C39: booking ของ therapist1 | D39: therapist1 แล้ว therapist2: GET /api/bookings/{id} | E39: therapist1 200 • therapist2 403 | F39: therapist1 200 • therapist2 403 | G39: Pass

Sheet IT07_AvailabilityApi_BVA
A1: Test Case Design and Test Results | J1: ห้อง SINGLE ที่เหลือ | K1: หมอนวด THAI ที่เหลือ | L1: เวลาปิดร้าน (60 นาที)
I2: min | J2: 0 | K2: 0 | L2: 12:00 → 2 รอบ
A3: Project Name: | B3: ตรวจช่วงเวลาว่าง: BookingController → AvailabilityServiceImpl → BusinessHours/Skill/Room/Booking repositories | E3: Student ID: | F3: 673380049-4 | I3: min+ | J3: 1 | K3: 3 | L3: −
A4: Test Strategy: | B4: Integration testing - Boundary Value (จำนวนทรัพยากรที่เหลือ และเวลาปิดร้าน) | E4: Designer: | F4: Piyachayanin | I4: nom | J4: 2 | K4: 4 | L4: 22:00 → 12 รอบ
A5: Test Environtment: | B5: Lenovo LOQ 15AHP11, CPU AMD Ryzen 7 250, Memory 16 GB DDR5, GPU NVIDIA GeForce RTX 5050 Laptop, OS Window 11 | E5: Date: | F5: 46305
A6: Method under test: | B6: GET /api/bookings/availability?date=D&serviceId=THAI&durationMinutes=60
A7: Requirement อ้างอิง: | B7: UC-08 • SRS 3.3 (เวลาทำการ) • BR-RES-01
A9: Test Case ID | B9: Input | D9: Expected Result | E9: Actual Result | F9: Status (Pass/Fail/No run)
B10: การจองในวัน D | C10: Request
A11: IT07-TC001 | B11: ไม่มี | C11: durationMinutes = 60 | D11: 12 รอบ (10:00–21:00) ว่างทุกรอบ • ทุกรอบมีห้อง 2 หมอนวด 4 | E11: 12 รอบ (10:00–21:00) ว่างทุกรอบ • ทุกรอบมีห้อง 2 หมอนวด 4 | F11: Pass
A12: IT07-TC002 | B12: therapist1 + Room 1 11:00–12:00 | C12: 60 | D12: รอบ 11:00 available = true • ห้องเหลือ 1 (Room 2) • หมอนวดเหลือ 3 | E12: รอบ 11:00 available = true • ห้องเหลือ 1 (Room 2) • หมอนวดเหลือ 3 | F12: Pass
A13: IT07-TC003 | B13: Room 1 และ Room 2 11:00–12:00 | C13: 60 | D13: รอบ 11:00 available = false (ห้องเหลือ 0) | E13: รอบ 11:00 available = false (ห้องเหลือ 0) | F13: Pass
A14: IT07-TC004 | B14: Room 1 และ Room 2 11:00–12:00 | C14: 60 | D14: รอบ 10:00 และ 12:00 available = false (buffer 15 นาที) • รอบ 13:00 available = true | E14: รอบ 10:00 และ 12:00 available = false (buffer 15 นาที) • รอบ 13:00 available = true | F14: Pass
A15: IT07-TC005 | B15: Room 1 และ Room 2 11:00–12:00 แต่ CANCELLED | C15: 60 | D15: รอบ 11:00 available = true | E15: รอบ 11:00 available = true | F15: Pass
A16: IT07-TC006 | B16: หมอนวด THAI ทั้ง 4 คน 15:00–16:00 (ห้องอื่น) | C16: 60 | D16: รอบ 15:00 available = false (หมอนวดเหลือ 0, ห้องเหลือ 2) | E16: รอบ 15:00 available = false (หมอนวดเหลือ 0, ห้องเหลือ 2) | F16: Pass
A17: IT07-TC007 | B17: ร้านปิดวันนั้น (business_hours.is_closed) | C17: 60 | D17: 200 availableSlots ว่าง (0 รอบ) | E17: 200 availableSlots ว่าง (0 รอบ) | F17: Pass
A18: IT07-TC008 | B18: ร้านเปิด 10:00–12:00 | C18: 60 | D18: 2 รอบ: 10:00, 11:00 (รอบสุดท้ายจบตรงเวลาปิด) | E18: 2 รอบ: 10:00, 11:00 (รอบสุดท้ายจบตรงเวลาปิด) | F18: Pass
A19: IT07-TC009 | B19: ไม่มี | C19: durationMinutes = 90 | D19: 11 รอบ (10:00–20:00) | E19: 11 รอบ (10:00–20:00) | F19: Pass
A20: IT07-TC010 | B20: − | C20: serviceId ไม่มีจริง / บริการถูกปิด | D20: 404 / 400 | E20: 404 / 400 | F20: Pass

Sheet IT08_CancelApi_DT
A1: Condition | B1: Rule#1 | C1: Rule#2 | D1: Rule#3 | E1: Rule#4 | F1: Rule#5
A2: C1: ผู้ยกเลิกเป็นพนักงาน | B2: N | C2: N | D2: N | E2: Y | F2: Y
A3: C2: เป็นเจ้าของ booking | B3: Y | C3: Y | D3: N | E3: − | F3: −
A4: C3: เหลือเวลามากกว่า 2 ชม. | B4: Y | C4: N | D4: − | E4: − | F4: −
A5: C4: สถานะยกเลิกได้ (PENDING/CONFIRMED/CHECKED_IN) | B5: Y | C5: − | D5: − | E5: Y | F5: N
A6: Action
A7: A1: 200 CANCELLED + note | B7: X | E7: X
A8: A2: 400 กฎ 2 ชม. | C8: X
A9: A3: 403 | D9: X
A10: A4: 400 จาก State | F10: X
A11: Impossible
A13: Test Case Design and Test Results
A15: Project Name: | B15: ยกเลิกการจอง: BookingController → BookingServiceImpl → State Pattern → PostgreSQL | F15: Student ID: | G15: 673380049-4
A16: Test Strategy: | B16: Integration testing - Decision Table (Limited Entry) | F16: Designer: | G16: Piyachayanin
A17: Test Environtment: | B17: Lenovo LOQ 15AHP11, CPU AMD Ryzen 7 250, Memory 16 GB DDR5, GPU NVIDIA GeForce RTX 5050 Laptop, OS Window 11 | F17: Date: | G17: 46305
A18: Method under test: | B18: PATCH /api/bookings/{id}/cancel (body {reason} ไม่บังคับ)
A19: Requirement อ้างอิง: | B19: UC-10 (A1 คืนเงิน) • BR-BKG-04 (ยกเลิกก่อน 2 ชม.)
A21: Rule# | B21: Test Case ID | C21: Input | E21: Expected Result | F21: Actual Result | G21: Status (Pass/Fail/No run)
C22: booking | D22: ผู้เรียก / body
A23: R1 | B23: IT08-TC001 | C23: ของตัวเอง วัน D 11:00 CONFIRMED | D23: customer {reason:"ติดธุระ"} | E23: 200 CANCELLED • specialNotes ลงท้าย "[Cancelled by CUSTOMER: ติดธุระ]" • ในฐานข้อมูลเปลี่ยนจริง | F23: 200 | G23: Pass
A24: R2 | B24: IT08-TC002 | C24: ของตัวเอง เริ่มในอีก 1 ชม. | D24: customer | E24: 400 "...at least 2 hours..." • สถานะเดิม | F24: 400 | G24: Pass
A25: R1 | B25: IT08-TC003 | C25: ของตัวเอง เริ่มในอีก 2 ชม. 10 นาที | D25: customer | E25: 200 CANCELLED | F25: 200 | G25: Pass
A26: R3 | B26: IT08-TC004 | C26: ของลูกค้าอื่น | D26: customer | E26: 403 "...only cancel your own bookings" | F26: 403 | G26: Pass
A27: R4 | B27: IT08-TC005 | C27: เริ่มในอีก 1 ชม. | D27: receptionist {reason:"ลูกค้าโทรแจ้ง"} | E27: 200 note "[Cancelled by RECEPTIONIST: ลูกค้าโทรแจ้ง]" | F27: 200 | G27: Pass
A28: R5 | B28: IT08-TC006 | C28: COMPLETED | D28: receptionist | E28: 400 "Cannot execute action 'cancel'..." | F28: 400 | G28: Pass
A29: R1 | B29: IT08-TC007 | C29: ของตัวเอง วัน D | D29: customer ไม่ส่ง body | E29: 200 note "[Cancelled by CUSTOMER: Cancelled by user]" | F29: 200 | G29: Pass
A30: R1 | B30: IT08-TC008 | C30: ของตัวเอง วัน D ชำระเงินแล้ว 500 | D30: customer | E30: 200 และ payment ถูกคืนเงิน (REFUNDED หรือมี refund 500.00) | F30: 200 | G30: Pass

Sheet IT09_PaymentRefundApi_EC
A1: Equivalence Class Design
A2: Valid EC | E2: Invalid EC
A3: EC ID | B3: Condition | E3: EC ID | F3: Condition
A4: V1 | B4: ชำระครั้งแรก ไม่มีโค้ด | E4: I1 | F4: ชำระซ้ำ
A5: V2 | B5: โค้ด FIWDEE20 / WELCOME100 | E5: I2 | F5: คืนเกินยอดคงเหลือ
A6: V3 | B6: โค้ดไม่ถูกต้อง → ไม่ลด | E6: I3 | F6: id ใน URL ไม่ตรง body
A7: V4 | B7: ขอใบเสร็จ | E7: I4 | F7: ช่องทางชำระล้มเหลว
A8: V5 | B8: คืนบางส่วน / คืนครบ | E8: I5 | F8: booking ถูกยกเลิก
A9: V6 | B9: รายงานรายได้รวมจากฐานข้อมูล | E9: I6 | F9: ลูกค้าดู payment ของคนอื่น
A11: Test Case Design and Test Results
A13: Project Name: | B13: ชำระเงินและคืนเงิน: Payment/RefundController → Service → Strategy (ของจริง) → PostgreSQL | H13: Student ID: | I13: 673380049-4
A14: Test Strategy: | B14: Integration testing - Weak Robust Equivalence Class (+ Stub ที่ Payment Strategy) | H14: Designer: | I14: Piyachayanin
A15: Test Environtment: | B15: Lenovo LOQ 15AHP11, CPU AMD Ryzen 7 250, Memory 16 GB DDR5, GPU NVIDIA GeForce RTX 5050 Laptop, OS Window 11 | H15: Date: | I15: 46305
A16: Method under test: | B16: POST /api/bookings/{id}/payment • GET /api/payments/{id}/receipt • POST /api/payments/{id}/refund • GET /api/admin/reports/revenue
A17: Requirement อ้างอิง: | B17: UC-19, UC-19a, UC-19b, UC-20 • UC-10 • UC-22
A19: Test Case ID | B19: Input | D19: Expected Result | E19: Actual Result | F19: Status (Pass/Fail/No run)
B20: ข้อมูลตั้งต้น | C20: Request
A21: IT09-TC001 | B21: booking PENDING 500 | C21: receptionist: CASH | D21: (V1) 200 net 500.00 • payments มี 1 แถว COMPLETED, paid_at ไม่ null • booking เป็น CONFIRMED | E21: 200 net 500.00 | F21: Pass
A22: IT09-TC002 | B22: booking PENDING 500 | C22: promoCode "FIWDEE20" | D22: (V2) discount 100.00, net 400.00 | E22: discount 100.00, net 400.00 | F22: Pass
A23: IT09-TC003 | B23: booking PENDING 500 | C23: promoCode "welcome100" (ตัวเล็ก) | D23: (V2) discount 100.00, net 400.00 | E23: discount 100.00, net 400.00 | F23: Pass
A24: IT09-TC004 | B24: booking PENDING 500 | C24: promoCode "XYZ" | D24: (V3) 200 discount 0, net 500.00 | E24: 200 discount 0, net 500.00 | F24: Pass
A25: IT09-TC005 | B25: ชำระแล้ว | C25: ชำระอีกครั้ง | D25: (I1) 409 • ยังมี payment 1 แถว | E25: 409 | F25: Pass
A26: IT09-TC006 | B26: ชำระแล้ว | C26: GET /payments/{id}/receipt | D26: (V4) 200 receiptNumber ตรงกับฐานข้อมูล • shopName "FIWDEE Massage" | E26: 200 | F26: Pass
A27: IT09-TC007 | B27: ชำระแล้ว 500 | C27: refund 200 | D27: (V5) 200 refunds มี 1 แถว COMPLETED • payment ยัง COMPLETED | E27: 200 | F27: Pass
A28: IT09-TC008 | B28: คืนแล้ว 200 (request ก่อนหน้า) | C28: refund 301 | D28: (I2) 400 "...exceeds maximum remaining refundable balance (300.00)" • ยอดคืนรวมยัง 200 | E28: 400 | F28: Pass
A29: IT09-TC009 | B29: คืนแล้ว 200 (request ก่อนหน้า) | C29: refund 300 | D29: (V5) 200 • payment เป็น REFUNDED | E29: 200 | F29: Pass
A30: IT09-TC010 | B30: ชำระแล้ว | C30: POST /payments/{id}/refund body paymentId = id อื่น | D30: (I3) 400 "Payment ID in URL...does not match..." | E30: 400 | F30: Pass
A31: IT09-TC011 | B31: stub: CashPaymentStrategy คืน false | C31: CASH | D31: (I4) 400 "Payment execution failed..." • booking ยัง PENDING | E31: 400 | F31: Pass
A32: IT09-TC012 | B32: stub: CashPaymentStrategy คืน false | C32: CASH | D32: (I4) มี payment สถานะ FAILED 1 แถวเป็นหลักฐาน | E32: มี payment สถานะ FAILED 1 แถวเป็นหลักฐาน | F32: Pass
A33: IT09-TC013 | B33: booking ถูกยกเลิกแล้ว | C33: CASH | D33: (I5) 400 ห้ามรับเงิน | E33: 400 | F33: Pass
A34: IT09-TC014 | B34: payment ของลูกค้า A | C34: ลูกค้า B: GET /bookings/{id}/payment | D34: (I6) 403 | E34: 403 | F34: Pass
A35: IT09-TC015 | B35: ชำระ 500 แล้วคืน 200 วันนี้ | C35: owner: GET /admin/reports/revenue วันนี้–วันนี้ | D35: (V6) netRevenue 500.00, refundedTotal 200.00, totalCompletedBookings 1 | E35: netRevenue 500.00, refundedTotal 200.00, totalCompletedBookings 1 | F35: Pass

Sheet IT10_CheckInQueue_EC
A1: Equivalence Class Design
A2: Valid EC | E2: Invalid EC
A3: EC ID | B3: Condition | E3: EC ID | F3: Condition
A4: V1 | B4: check-in ครั้งแรก → คิวใหม่ | E4: I1 | F4: นัดไม่ใช่วันนี้
A5: V2 | B5: check-in ซ้ำ → คิวเดิม | E5: I2 | F5: booking ยังไม่ยืนยัน
A6: V3 | B6: เรียกคิวถัดไป | E6: I3 | F6: ไม่มีคิวรอ
A7: V4 | B7: ดูคิววันนี้ / คิวของหมอนวด | E7: I4 | F7: เปลี่ยนสถานะคิวข้ามขั้น
E8: I5 | F8: check-in ผ่าน PATCH /status
A10: Test Case Design and Test Results
A12: Project Name: | B12: Check-in และคิว: FrontDesk/QueueController → QueueServiceImpl → Event → QueueListener (Observer) → PostgreSQL | H12: Student ID: | I12: 673380049-4
A13: Test Strategy: | B13: Integration testing - Weak Robust Equivalence Class (+ Spy ที่ QueueListener) | H13: Designer: | I13: Piyachayanin
A14: Test Environtment: | B14: Lenovo LOQ 15AHP11, CPU AMD Ryzen 7 250, Memory 16 GB DDR5, GPU NVIDIA GeForce RTX 5050 Laptop, OS Window 11 | H14: Date: | I14: 46305
A15: Method under test: | B15: PATCH /api/bookings/{id}/check-in • POST /api/admin/queue/call-next • PATCH /api/admin/queue/{id}/status • GET /api/admin/queue • GET /api/therapist/me/schedule
A16: Requirement อ้างอิง: | B16: UC-12, UC-13, UC-14 • design-patterns.md (Observer) • BR-QUE-01
A18: Test Case ID | B18: Input | D18: Expected Result | E18: Actual Result | F18: Status (Pass/Fail/No run)
B19: ข้อมูลตั้งต้น | C19: Request (receptionist)
A20: IT10-TC001 | B20: booking A วันนี้ CONFIRMED | C20: PATCH /bookings/A/check-in | D20: (V1) 200 queueNumber Q001 WAITING • bookings.status = CHECKED_IN • QueueListener ถูกเรียก 1 ครั้งด้วย event → CHECKED_IN | E20: 200 | F20: Pass
A21: IT10-TC002 | B21: A check-in แล้ว, B วันนี้ CONFIRMED | C21: check-in B | D21: (V1) Q002 | E21: Q002 | F21: Pass
A22: IT10-TC003 | B22: A check-in แล้ว | C22: check-in A อีกครั้ง | D22: (V2) 200 queueId เดิม • queue_items ของ A มี 1 แถว | E22: 200 | F22: Pass
A23: IT10-TC004 | B23: booking พรุ่งนี้ CONFIRMED | C23: check-in | D23: (I1) 400 "...only be checked in on its scheduled date" | E23: 400 | F23: Pass
A24: IT10-TC005 | B24: booking วันนี้ PENDING | C24: check-in | D24: (I2) 400 "Only confirmed bookings can be checked in" | E24: 400 | F24: Pass
A25: IT10-TC006 | B25: Q001 และ Q002 WAITING | C25: POST /admin/queue/call-next | D25: (V3) 200 Q001 CALLED, calledTime ไม่ null • Q002 ยัง WAITING | E25: 200 | F25: Pass
A26: IT10-TC007 | B26: ไม่มีคิว WAITING | C26: call-next | D26: (I3) 404 | E26: 404 | F26: Pass
A27: IT10-TC008 | B27: Q001 WAITING | C27: PATCH /admin/queue/{id}/status COMPLETED | D27: (I4) 400 • สถานะในฐานข้อมูลยัง WAITING | E27: 400 | F27: Pass
A28: IT10-TC009 | B28: Q001, Q002 | C28: GET /admin/queue?date=วันนี้ | D28: (V4) 200 ได้ 2 รายการ Q001 ก่อน Q002 | E28: 200 | F28: Pass
A29: IT10-TC010 | B29: booking วันนี้ CONFIRMED | C29: PATCH /bookings/{id}/status?status=CHECKED_IN | D29: (I5) 200 และมีคิวถูกสร้าง | E29: 200 | F29: Pass
A30: IT10-TC011 | B30: A (therapist1) check-in แล้ว | C30: therapist1: GET /therapist/me/schedule?therapistId=therapist1 | D30: (V4) 200 มี Q001 | E30: 200 | F30: Pass

Sheet IT11_EndToEndFlow_SC
A1: Equivalence Class Design
A2: Valid EC | E2: Invalid EC
A3: EC ID | B3: Condition | E3: EC ID | F3: Condition
A4: P1 | B4: Walk-in: check-in → เรียก → เริ่ม → จบ → ชำระ → รีวิว | E4: X1 | F4: ตรวจสถานะกลางทาง: จบงานก่อนชำระ
A5: P2 | B5: ลูกค้าออนไลน์: ดูรอบว่าง → จอง → ชำระล่วงหน้า | E5: X2 | F5: ชำระก่อนหมอนวดกดจบงาน
A6: P3 | B6: ยกเลิกแล้วรอบเวลาว่างกลับมา | E6: X3 | F6: รีวิวโดยผู้ใช้ที่ไม่ใช่เจ้าของ
E7: X4 | F7: จองช่วงเดียวกันพร้อมกันหลาย request
E8: X5 | F8: รีวิวก่อนรับบริการ
A10: Test Case Design and Test Results
A12: Project Name: | B12: Flow ทั้งระบบตาม sequence diagram (หลาย controller ต่อเนื่องกันบนฐานข้อมูลเดียว) | H12: Student ID: | I12: 673380049-4
A13: Test Strategy: | B13: Integration testing - Scenario-based (Use-case flow) แบ่งกลุ่มแบบ Equivalence Class ของเส้นทาง | H13: Designer: | I13: Piyachayanin
A14: Test Environtment: | B14: Lenovo LOQ 15AHP11, CPU AMD Ryzen 7 250, Memory 16 GB DDR5, GPU NVIDIA GeForce RTX 5050 Laptop, OS Window 11 | H14: Date: | I14: 46305
A15: Method under test: | B15: check-in → call-next → start → complete → payment → review • online booking • cancel • concurrency
A16: Requirement อ้างอิง: | B16: sequence-diagram.md Scenario 1–3 • UC-07–UC-19 • SRS 7.1 (State diagram)
A18: Test Case ID | B18: Input | D18: Expected Result | E18: Actual Result | F18: Status (Pass/Fail/No run)
B19: เส้นทาง | C19: ขั้นตอน
A20: IT11-TC001 | B20: P1 Walk-in (ลำดับตาม Scenario 3) | C20: check-in → call-next → therapist1 start → therapist1 complete → receptionist ชำระ CASH → ลูกค้ารีวิว 5/5/5 | D20: จบที่ booking COMPLETED, คิว COMPLETED, Room 1 CLEANING, payment COMPLETED 500.00, review 1 แถว, therapist1 average_rating 5.00 | E20: จบที่ booking COMPLETED, คิว COMPLETED, Room 1 CLEANING, payment COMPLETED 500.00, review 1 แถว, therapist1 average_rating 5.00 | F20: Pass
A21: IT11-TC002 | B21: X1 จุดตรวจกลางทาง | C21: เหมือน P1 แต่ตรวจหลัง therapist complete (ยังไม่ชำระ) | D21: booking ยัง IN_SERVICE รอชำระ | E21: booking ยัง IN_SERVICE รอชำระ | F21: Pass
A22: IT11-TC003 | B22: X2 ชำระก่อนจบงาน | C22: check-in → call-next → start → ชำระ CASH | D22: booking COMPLETED และคิว COMPLETED, ห้อง CLEANING (Scenario 3 Phase D) | E22: booking COMPLETED และคิว COMPLETED, ห้อง CLEANING | F22: Pass
A23: IT11-TC004 | B23: P2 ลูกค้าออนไลน์ | C23: สมัคร → availability วัน D → จองรอบ 13:00 ตามหมอนวด/ห้องที่ระบบเสนอ → ชำระ QR_PROMPTPAY → GET /bookings/my → availability อีกครั้ง | D23: 201 PENDING → ชำระแล้ว CONFIRMED • my bookings แสดง CONFIRMED • รอบ 13:00 ห้องเหลือ 1 | E23: 201 PENDING → ชำระแล้ว CONFIRMED • my bookings แสดง CONFIRMED • รอบ 13:00 ห้องเหลือ 1 | F23: Pass
A24: IT11-TC005 | B24: P3 ยกเลิกแล้วว่าง | C24: ลูกค้า 2 คนจอง Room 1 และ Room 2 วัน D 14:00 → availability → ลูกค้าคนแรกยกเลิก → availability | D24: ก่อนยกเลิก 14:00 available = false • หลังยกเลิก available = true | E24: ก่อนยกเลิก 14:00 available = false • หลังยกเลิก available = true | F24: Pass
A25: IT11-TC006 | B25: X3 รีวิวผิดคน | C25: booking COMPLETED ของลูกค้า A • ลูกค้า B POST /bookings/{id}/review | D25: 403 | E25: 403 | F25: Pass
A26: IT11-TC007 | B26: X4 จองพร้อมกัน | C26: 8 request พร้อมกัน: therapist1, Room 1, วัน D (ทำ 3 รอบ: 14:00, 15:00, 16:00) | D26: ทุกรอบสำเร็จ 1 request (201) ที่เหลือ 409 • ฐานข้อมูลมี booking รอบละ 1 แถว | E26: ทุกรอบสำเร็จ 1 request (201) ที่เหลือ 409 • ฐานข้อมูลมี booking รอบละ 1 แถว | F26: Pass
A27: IT11-TC008 | B27: X5 รีวิวก่อนใช้บริการ | C27: booking CONFIRMED • เจ้าของรีวิว | D27: 400 "...only be submitted for a completed booking" | E27: 400 | F27: Pass

Sheet IT12_AdminConfigImpact_EC
A1: Equivalence Class Design
A2: Valid EC | E2: Invalid EC
A3: EC ID | B3: Condition | E3: EC ID | F3: Condition
A4: V1 | B4: เพิ่ม/ปิดห้อง | E4: I1 | F4: หมอนวดที่สร้างผ่านหลังบ้านไม่มีรหัสผ่าน
A5: V2 | B5: เพิ่ม/ปิดบริการ | E5: I2 | F5: receptionist แก้ข้อมูลที่เป็นสิทธิ์ owner
A6: V3 | B6: ตั้งวันหยุดหมอนวด
A7: V4 | B7: ปิดร้านบางวัน
A9: Test Case Design and Test Results
A11: Project Name: | B11: ผลของการตั้งค่าหลังบ้านต่อการจอง: AdminResourceController → Room/Service/Therapist/Shop service → Booking/Availability | H11: Student ID: | I11: 673380049-4
A12: Test Strategy: | B12: Integration testing - Weak Robust Equivalence Class (ข้ามโมดูล) | H12: Designer: | I12: Piyachayanin
A13: Test Environtment: | B13: Lenovo LOQ 15AHP11, CPU AMD Ryzen 7 250, Memory 16 GB DDR5, GPU NVIDIA GeForce RTX 5050 Laptop, OS Window 11 | H13: Date: | I13: 46305
A14: Method under test: | B14: POST/DELETE /api/admin/rooms • POST/DELETE /api/admin/services • PUT /api/admin/therapists/{id}/schedules • PUT /api/admin/shop • POST /api/admin/therapists
A15: Requirement อ้างอิง: | B15: UC-23–UC-27 • UC-07, UC-08
A17: Test Case ID | B17: Input | D17: Expected Result | E17: Actual Result | F17: Status (Pass/Fail/No run)
B18: การตั้งค่า (owner) | C18: ตรวจผลที่
A19: IT12-TC001 | B19: POST /admin/rooms "IT-R1" SINGLE | C19: availability THAI วัน D | D19: (V1) 201 • รอบ 10:00 มีห้อง 3 ห้อง | E19: 201 | F19: Pass
A20: IT12-TC002 | B20: DELETE /admin/rooms/{Room 2} | C20: availability THAI วัน D | D20: (V1) 200 • รอบ 10:00 มีห้อง 1 ห้อง (Room 1) | E20: 200 | F20: Pass
A21: IT12-TC003 | B21: POST /admin/services "IT-SPA" [60/1000] | C21: GET /api/services (ไม่ login) | D21: (V2) 201 • รายการมี IT-SPA และตัวเลือก 60 นาที 1000 | E21: 201 | F21: Pass
A22: IT12-TC004 | B22: DELETE /admin/services/{THAI} | C22: ลูกค้าจอง THAI • GET /api/services | D22: (V2) จอง 400 "Selected service is inactive" • รายการไม่มี THAI | E22: 400 | F22: Pass
A23: IT12-TC005 | B23: PUT /admin/therapists/{therapist1}/schedules วัน D dayOff | C23: ลูกค้าจอง therapist1 วัน D 11:00 | D23: (V3) 200 • จอง 409 "...is off on this date" | E23: 200 | F23: Pass
A24: IT12-TC006 | B24: PUT /admin/shop ทั้ง 7 วัน โดยวันของ D ปิด | C24: availability THAI วัน D | D24: (V4) 200 • 0 รอบ | E24: 200 | F24: Pass
A25: IT12-TC007 | B25: POST /admin/therapists "it.newtherapist" | C25: users.password_hash | D25: (I1) มีรหัสผ่านให้ login ได้ | E25: null | F25: Pass
A26: IT12-TC008 | B26: receptionist: POST /admin/rooms | C26: HTTP status | D26: (I2) 403 (UC-24 เป็นสิทธิ์ Owner) | E26: 403 | F26: Pass
